<robot
  name="pf_description">
  <link
    name="base_link">
    <inertial>
      <origin
        xyz="0.0163800057609369 -4.06842607302539E-06 0.123213166422444"
        rpy="0 0 0" />
      <mass
        value="4.28547466433498" />
      <inertia
        ixx="0.0785677617353809"
        ixy="-2.9016419671321E-06"
        ixz="0.00880098589117479"
        iyy="0.131430039367021"
        iyz="-2.79291610866049E-06"
        izz="0.170626119167957" />
    </inertial>
    <visual>
      <origin
        xyz="0 0 0"
        rpy="0 0 0" />
      <geometry>
        <mesh
          filename="package://pf_description/meshes/base_link.STL" />
      </geometry>
      <material
        name="">
        <color
          rgba="0.752941176470588 0.752941176470588 0.752941176470588 1" />
      </material>
    </visual>
    <collision>
      <origin
        xyz="0 0 0"
        rpy="0 0 0" />
      <geometry>
        <mesh
          filename="package://pf_description/meshes/base_link.STL" />
      </geometry>
    </collision>
  </link>
  <link
    name="front_left_wheel_link">
    <inertial>
      <origin
        xyz="0.0645845783403295 0 1.38777878078145E-17"
        rpy="0 0 0" />
      <mass
        value="1.34458504328816" />
      <inertia
        ixx="0.00556891834008019"
        ixy="-1.61193135467668E-19"
        ixz="1.17794337584903E-19"
        iyy="0.00306681058053119"
        iyz="-8.93494629223616E-35"
        izz="0.00306681058053119" />
    </inertial>
    <visual>
      <origin
        xyz="0 0 0"
        rpy="0 0 0" />
      <geometry>
        <mesh
          filename="package://pf_description/meshes/front_left_wheel_link.STL" />
      </geometry>
      <material
        name="">
        <color
          rgba="1 1 1 1" />
      </material>
    </visual>
    <collision>
      <origin
        xyz="0 0 0"
        rpy="0 0 0" />
      <geometry>
        <mesh
          filename="package://pf_description/meshes/front_left_wheel_link.STL" />
      </geometry>
    </collision>
  </link>
  <joint
    name="front_left_wheel"
    type="continuous">
    <origin
      xyz="0.151424577883419 0.1392 0.0946692626906409"
      rpy="3.14159265358979 6.12303176911189E-17 1.5707963267949" />
    <parent
      link="base_link" />
    <child
      link="front_left_wheel_link" />
    <axis
      xyz="1 0 0" />
  </joint>
  <link
    name="front_right_wheel_link">
    <inertial>
      <origin
        xyz="0.0645845783403309 5.55111512312578E-17 -4.30211422042248E-16"
        rpy="0 0 0" />
      <mass
        value="1.34458504328816" />
      <inertia
        ixx="0.00556891834008019"
        ixy="-1.44322493928414E-18"
        ixz="1.73879958609898E-17"
        iyy="0.00306681058053119"
        iyz="9.98588749872954E-33"
        izz="0.00306681058053119" />
    </inertial>
    <visual>
      <origin
        xyz="0 0 0"
        rpy="0 0 0" />
      <geometry>
        <mesh
          filename="package://pf_description/meshes/front_right_wheel_link.STL" />
      </geometry>
      <material
        name="">
        <color
          rgba="1 1 1 1" />
      </material>
    </visual>
    <collision>
      <origin
        xyz="0 0 0"
        rpy="0 0 0" />
      <geometry>
        <mesh
          filename="package://pf_description/meshes/front_right_wheel_link.STL" />
      </geometry>
    </collision>
  </link>
  <joint
    name="front_right_wheel"
    type="continuous">
    <origin
      xyz="0.15142457788342 -0.139199999999998 0.0946692626906405"
      rpy="3.14159265358979 -6.12303176911189E-17 -1.5707963267949" />
    <parent
      link="base_link" />
    <child
      link="front_right_wheel_link" />
    <axis
      xyz="-1 0 0" />
  </joint>
  <link
    name="rear_left_wheel_link">
    <inertial>
      <origin
        xyz="0.0645845783403295 0 0"
        rpy="0 0 0" />
      <mass
        value="1.34458504328816" />
      <inertia
        ixx="0.00556891834008019"
        ixy="-1.61182539813231E-19"
        ixz="-9.91485339660147E-21"
        iyy="0.00306681058053119"
        iyz="8.31360473337875E-35"
        izz="0.00306681058053119" />
    </inertial>
    <visual>
      <origin
        xyz="0 0 0"
        rpy="0 0 0" />
      <geometry>
        <mesh
          filename="package://pf_description/meshes/rear_left_wheel_link.STL" />
      </geometry>
      <material
        name="">
        <color
          rgba="1 1 1 1" />
      </material>
    </visual>
    <collision>
      <origin
        xyz="0 0 0"
        rpy="0 0 0" />
      <geometry>
        <mesh
          filename="package://pf_description/meshes/rear_left_wheel_link.STL" />
      </geometry>
    </collision>
  </link>
  <joint
    name="rear_left_wheel"
    type="continuous">
    <origin
      xyz="-0.15157542211658 0.1392 0.0946692626906423"
      rpy="3.14159265358979 6.12303176911189E-17 1.5707963267949" />
    <parent
      link="base_link" />
    <child
      link="rear_left_wheel_link" />
    <axis
      xyz="1 0 0" />
  </joint>
  <link
    name="rear_right_wheel_link">
    <inertial>
      <origin
        xyz="0.0645845783403308 5.55111512312578E-17 -4.30211422042248E-16"
        rpy="0 0 0" />
      <mass
        value="1.34458504328816" />
      <inertia
        ixx="0.00556891834008019"
        ixy="-1.92357574458696E-18"
        ixz="1.71626082329745E-17"
        iyy="0.00306681058053119"
        iyz="1.30685870267575E-32"
        izz="0.00306681058053119" />
    </inertial>
    <visual>
      <origin
        xyz="0 0 0"
        rpy="0 0 0" />
      <geometry>
        <mesh
          filename="package://pf_description/meshes/rear_right_wheel_link.STL" />
      </geometry>
      <material
        name="">
        <color
          rgba="1 1 1 1" />
      </material>
    </visual>
    <collision>
      <origin
        xyz="0 0 0"
        rpy="0 0 0" />
      <geometry>
        <mesh
          filename="package://pf_description/meshes/rear_right_wheel_link.STL" />
      </geometry>
    </collision>
  </link>
  <joint
    name="rear_right_wheel"
    type="continuous">
    <origin
      xyz="-0.15157542211658 -0.139199999999997 0.0946692626906433"
      rpy="3.14159265358979 -6.12303176911189E-17 -1.5707963267949" />
    <parent
      link="base_link" />
    <child
      link="rear_right_wheel_link" />
    <axis
      xyz="-1 0 0" />
  </joint>
  <link
    name="laser">
    <inertial>
      <origin
        xyz="0.012884 0.00113 -0.013995"
        rpy="0 0 0" />
      <mass
        value="0.078385" />
      <inertia
        ixx="3.5328E-05"
        ixy="-1.1835E-06"
        ixz="-9.6166E-06"
        iyy="6.6075E-05"
        iyz="1.7088E-06"
        izz="7.775E-05" />
    </inertial>
    <visual>
      <origin
        xyz="0 0 0"
        rpy="0 0 0" />
      <geometry>
        <mesh
          filename="package://pf_description/meshes/laser.STL" />
      </geometry>
      <material
        name="">
        <color
          rgba="0.75294 0.75294 0.75294 1" />
      </material>
    </visual>
    <collision>
      <origin
        xyz="0 0 0"
        rpy="0 0 0" />
      <geometry>
        <mesh
          filename="package://pf_description/meshes/laser.STL" />
      </geometry>
    </collision>
  </link>
  <joint
    name="laser_joint"
    type="fixed">
    <origin
      xyz="0.17492 0 0.31627"
      rpy="-5.4899E-15 0 3.1416" />
    <parent
      link="base_link" />
    <child
      link="laser" />
    <axis
      xyz="0 0 0" />
  </joint>
</robot>